<?xml version="1.0" ?>
<!-- =================================================================================== -->
<!-- |    This document was autogenerated by xacro from description/autonomous_rover.urdf.xacro | -->
<!-- |    EDITING THIS FILE BY HAND IS NOT RECOMMENDED                                 | -->
<!-- =================================================================================== -->
<robot name="rover">
  <ros2_control name="GazeboSystem" type="system">
    <hardware>
      <plugin>gazebo_ros2_control/GazeboSystem </plugin>
    </hardware>
    <joint name="left_wheel_joint">
      <command_interface name="velocity">
        <param name="min"> -10 </param>
        <param name="max"> 10 </param>
      </command_interface>
      <state_interface name="velocity">
        <param name="initial_value"> 0.0 </param>
      </state_interface>
      <state_interface name="position">
        <param name="initial_value"> 0.0 </param>
      </state_interface>
    </joint>
    <joint name="right_wheel_joint">
      <command_interface name="velocity">
        <param name="min"> -10 </param>
        <param name="max"> 10 </param>
      </command_interface>
      <state_interface name="velocity">
        <param name="initial_value"> 0.0 </param>
      </state_interface>
      <state_interface name="position">
        <param name="initial_value"> 0.0 </param>
      </state_interface>
    </joint>
  </ros2_control>
  <gazebo>
    <plugin filename="libgazebo_ros2_control.so" name="gazebo_ros2_control">
      <parameters>/home/alberto/dev_ws/install/autonom_rover/share/autonom_rover/config/my_controllers.yaml</parameters>
    </plugin>
  </gazebo>
  <!-- Specify some colours -->
  <material name="white">
    <color rgba="1 1 1 1"/>
  </material>
  <material name="orange">
    <color rgba="1 0.3 0.1 1"/>
  </material>
  <material name="blue">
    <color rgba="0.2 0.2 1 1"/>
  </material>
  <material name="red">
    <color rgba=" 0.8 0.1 0.1 1"/>
  </material>
  <!-- Specify some standard inertial calculations https://en.wikipedia.org/wiki/List_of_moments_of_inertia -->
  <!-- These make use of xacro's mathematical functionality -->
  <!-- Base Link -->
  <link name="base_link">
    </link>
  <!-- Base to Chasis joint -->
  <joint name="chasis_joint" type="fixed">
    <parent link="base_link"/>
    <child link="chasis_link"/>
    <origin xyz="-0.07 0 0"/>
  </joint>
  <!-- Chasis of the robot -->
  <link name="chasis_link">
    <visual>
      <origin rpy="0 0 0" xyz="0.0875 0 0.0275"/>
      <geometry>
        <box size="0.175 0.105 0.055"/>
      </geometry>
      <material name="white"/>
    </visual>
    <collision>
      <origin rpy="0 0 0" xyz="0.0875 0 0.0275"/>
      <geometry>
        <box size="0.175 0.105 0.055"/>
      </geometry>
    </collision>
    <inertial>
      <origin rpy="0 0 0" xyz="0.0875 0 0.0275"/>
      <mass value="1"/>
      <inertia ixx="0.0011708333333333332" ixy="0.0" ixz="0.0" iyy="0.0028041666666666666" iyz="0.0" izz="0.0034708333333333327"/>
    </inertial>
  </link>
  <!-- Joint for Right wheel -->
  <joint name="right_wheel_joint" type="continuous">
    <parent link="chasis_link"/>
    <child link="right_wheel_link"/>
    <origin rpy="1.5707963267948966 0 0" xyz="0.07 -0.0675 0"/>
    <axis xyz="0 0 -1"/>
  </joint>
  <!-- Right wheel link -->
  <link name="right_wheel_link">
    <visual>
      <origin rpy="0 0 0" xyz="0 0 0"/>
      <geometry>
        <cylinder length="0.03" radius="0.035"/>
      </geometry>
      <material name="orange"/>
    </visual>
    <collision>
      <origin rpy="0 0 0" xyz="0 0 0"/>
      <geometry>
        <cylinder length="0.03" radius="0.035"/>
      </geometry>
    </collision>
    <inertial>
      <origin rpy="0 0 0" xyz="0 0 0"/>
      <mass value="0.08"/>
      <inertia ixx="3.0500000000000003e-05" ixy="0.0" ixz="0.0" iyy="3.0500000000000003e-05" iyz="0.0" izz="4.9000000000000005e-05"/>
    </inertial>
  </link>
  <!-- Joint for Left wheel -->
  <joint name="left_wheel_joint" type="continuous">
    <parent link="chasis_link"/>
    <child link="left_wheel_link"/>
    <origin rpy="-1.5707963267948966 0 0" xyz="0.07 0.0675 0"/>
    <axis xyz="0 0 1"/>
  </joint>
  <!-- Left wheel link -->
  <link name="left_wheel_link">
    <visual>
      <origin rpy="0 0 0" xyz="0 0 0"/>
      <geometry>
        <cylinder length="0.03" radius="0.035"/>
      </geometry>
      <material name="orange"/>
    </visual>
    <collision>
      <origin rpy="0 0 0" xyz="0 0 0"/>
      <geometry>
        <cylinder length="0.03" radius="0.035"/>
      </geometry>
    </collision>
    <inertial>
      <origin rpy="0 0 0" xyz="0 0 0"/>
      <mass value="0.08"/>
      <inertia ixx="3.0500000000000003e-05" ixy="0.0" ixz="0.0" iyy="3.0500000000000003e-05" iyz="0.0" izz="4.9000000000000005e-05"/>
    </inertial>
  </link>
  <!-- Joint for Front Wheel-->
  <joint name="wheel_front_joint" type="fixed">
    <origin xyz="0.16 0 -0.0175"/>
    <parent link="chasis_link"/>
    <child link="wheel_front_link"/>
  </joint>
  <!-- Link for Front wheel -->
  <link name="wheel_front_link">
    <visual>
      <origin rpy="0 0 0" xyz="0 0 0"/>
      <geometry>
        <sphere radius="0.0175"/>
      </geometry>
      <material name="blue"/>
    </visual>
    <collision>
      <origin rpy="0 0 0" xyz="0 0 0"/>
      <geometry>
        <sphere radius="0.0175"/>
      </geometry>
    </collision>
    <inertial>
      <origin rpy="0 0 0" xyz="0 0 0"/>
      <mass value="0.01"/>
      <inertia ixx="1.2250000000000001e-06" ixy="0.0" ixz="0.0" iyy="1.2250000000000001e-06" iyz="0.0" izz="1.2250000000000001e-06"/>
    </inertial>
  </link>
  <!-- Gazebo is unable to use the same <material> tags that are already in the URDF (that RViz uses). -->
  <!-- Instead, we need to add gazebo tags for our links that refer to Gazebo materials -->
  <gazebo reference="chasis_link">
    <material>Gazebo/Yellow</material>
  </gazebo>
  <gazebo reference="right_wheel_link">
    <material>Gazebo/Orange</material>
  </gazebo>
  <gazebo reference="left_wheel_link">
    <material>Gazebo/Orange</material>
  </gazebo>
  <gazebo reference="wheel_front_link">
    <material>Gazebo/Blue</material>
    <mu1 value="0.001"/>
    <mu2 value="0.001"/>
  </gazebo>
  <gazebo>
    <plugin filename="libgazebo_ros_joint_state_publisher.so" name="gazebo_ros_joint_state_publisher">
      <update_rate>20</update_rate>
      <joint_name>right_wheel_joint</joint_name>
      <joint_name>left_wheel_joint</joint_name>
    </plugin>
  </gazebo>
  <joint name="lidar_joint" type="fixed">
    <parent link="chasis_link"/>
    <child link="lidar_frame"/>
    <origin rpy="0 0 0" xyz="0.04 0 0.065"/>
  </joint>
  <link name="lidar_frame">
    <visual>
      <geometry>
        <cylinder length="0.02" radius="0.035"/>
      </geometry>
      <material name="red"/>
    </visual>
    <collision>
      <origin rpy="0 0 0" xyz="0 0 0"/>
      <geometry>
        <cylinder length="0.02" radius="0.035"/>
      </geometry>
    </collision>
    <inertial>
      <origin rpy="0 0 0" xyz="0 0 0"/>
      <mass value="0.08"/>
      <inertia ixx="3.0500000000000003e-05" ixy="0.0" ixz="0.0" iyy="3.0500000000000003e-05" iyz="0.0" izz="4.9000000000000005e-05"/>
    </inertial>
  </link>
  <gazebo reference="lidar_frame">
    <material>Gazebo/Red</material>
    <sensor name="lidar" type="ray">
      <pose> 0 0 0 0 0 0 </pose>
      <visualize> true </visualize>
      <update_rate>10</update_rate>
      <ray>
        <scan>
          <horizontal>
            <samples> 360 </samples>
            <resolution> 1 </resolution>
            <min_angle>-3.14</min_angle>
            <max_angle>3.14</max_angle>
          </horizontal>
        </scan>
        <range>
          <min>0.3</min>
          <max>12</max>
          <resolution> 1</resolution>
        </range>
      </ray>
      <plugin filename="libgazebo_ros_ray_sensor.so" name="laser_controller">
        <ros>
          <argument> ~/out:=scan </argument>
        </ros>
        <output_type> sensor_msgs/LaserScan </output_type>
        <frame_name> lidar_frame </frame_name>
      </plugin>
    </sensor>
  </gazebo>
</robot>
